<robot name="PF400_Robot">

  <!-- Materials -->

  <material name="white">
    <color rgba="1 1 1 1"/>
  </material>

  <material name="aluminum">
    <color rgba="0.6 0.6 0.6 1"/>
  </material>

  <!-- Links -->
  <link name="rail_base">
    <visual>
      <origin xyz="0.125 -0.0198 0" rpy="0 0 1.5708"/>
      <geometry>
        <mesh filename="package://pf400_description/meshes/rail_base.STL" scale="1 1 1"/>
      </geometry>
      <material name="white"/>
    </visual>
  </link>

  <link name="rail">
    <visual>
      <origin xyz="0.1309 -0.0198 0.0320" rpy="1.5708 0 1.5708"/>
      <geometry>
        <mesh filename="package://pf400_description/meshes/rail.STL" scale="1 1 1"/>
      </geometry>
      <material name="white"/>
    </visual>
  </link>

  <link name="z_column">
    <visual>
      <origin xyz="0 0 0.074" rpy="0 0 0"/>
      <geometry>
        <mesh filename="package://pf400_description/meshes/PF400_Z_Column.STL" scale="0.001 0.001 0.00132"/>
      </geometry>
      <material name="white"/>
    </visual>
  </link>

  <link name="z_carriage">
    <visual>
      <origin xyz="0 0 0.074" rpy="0 0 0"/>
      <geometry>
        <mesh filename="package://pf400_description/meshes/PF400_Z_Carriage.STL" scale="0.001 0.001 0.001"/>
      </geometry>
      <material name="white"/>
    </visual>
  </link>

  <link name="inner_link">
    <visual>
      <origin xyz="0 0 0.074" rpy="0 0 0"/>
      <geometry>
        <mesh filename="package://pf400_description/meshes/PF400_Inner_Link.STL" scale="0.001 0.001 0.001"/>
      </geometry>
      <material name="white"/>
    </visual>
  </link>

  <link name="outer_link">
    <visual>
      <origin xyz="0 0 0.074" rpy="0 0 0"/>
      <geometry>
        <mesh filename="package://pf400_description/meshes/PF400_Outer_Link.STL" scale="0.001 0.001 0.001"/>
      </geometry>
      <material name="white"/>
    </visual>
  </link>

  <link name="hand">
    <visual>
      <origin xyz="0 0 0.074" rpy="0 0 0"/>
      <geometry>
        <mesh filename="package://pf400_description/meshes/PF400_Hand.STL" scale="0.001 0.001 0.001"/>
      </geometry>
      <material name="white"/>
    </visual>
  </link>

  <link name="left_finger">
    <visual>
      <origin xyz="-0.02 -0.053 0.053" rpy="0 0 0"/>
      <geometry>
        <mesh filename="package://pf400_description/meshes/pf400_left_finger.STL" scale="0.001 0.001 0.001"/>
      </geometry>
      <material name="aluminum"/>
    </visual>
  </link>

  <link name="right_finger">
    <visual>
      <origin xyz="-0.021 -0.028 0.105" rpy="-1.5708 0 0"/>
      <geometry>
        <mesh filename="package://pf400_description/meshes/pf400_right_finger.STL" scale="0.001 0.001 0.001"/>
      </geometry>
      <material name="aluminum"/>
    </visual>
  </link>

  <!-- Joints -->

  <joint name="J1" type="prismatic">
    <parent link="z_column"/>
    <child link="z_carriage"/>
    <axis xyz="0 0 1"/>
    <origin xyz="0.03005 -0.0198 0.17535" rpy="0 0 0"/>
    <limit effort="1000.0" lower="0.002" upper="1.160" velocity="0.5"/>  </joint>
  </joint>

  <joint name="J2" type="revolute">
    <parent link="z_carriage"/>
    <child link="inner_link"/>
    <axis xyz="0 0 1"/>
    <origin xyz="0.173001 0.020 0.0235" rpy="0 0 0"/>
    <limit effort="1000.0" lower="-1.62316" upper="1.62316" velocity="0.5"/>
  </joint>

  <joint name="J3" type="revolute">
    <parent link="inner_link"/>
    <child link="outer_link"/>
    <axis xyz="0 0 1"/>
    <origin xyz="0.302 0 -0.072285" rpy="0 0 0"/>
    <limit effort="1000.0" lower="0.175" upper="6.1" velocity="0.5"/>
  </joint>

  <joint name="J4" type="revolute">
    <parent link="outer_link"/>
    <child link="hand"/>
    <axis xyz="0 0 1"/>
    <origin xyz="0.289 0 -0.032942" rpy="0 0 0"/>
    <limit effort="1000.0" lower="-16.7552" upper="16.7552" velocity="0.5"/>
  </joint>

  <joint name="J5" type="prismatic">
    <parent link="hand"/>
    <child link="left_finger"/>
    <axis xyz="0 1 0"/>
    <origin xyz="0.078573 0 -0.04269" rpy="0 0 0"/>
    <limit effort="1000.0" lower="0.067454" upper="0.070" velocity="0.5"/>
  </joint>

  <joint name="J5_mirror" type="prismatic">
    <parent link="hand"/>
    <child link="right_finger"/>
    <axis xyz="0 -1 0"/>
    <origin xyz="0.078573 0 -0.04269" rpy="0 0 0"/>
    <limit effort="1000.0" lower="0.067454" upper="0.070" velocity="0.5"/>
    <mimic joint="J5" multiplier="1"/>
  </joint>

  <joint name="J6" type="prismatic">
    <parent link="rail_base"/>
    <child link="rail"/>
    <axis xyz="1 0 0"/>
    <origin xyz="0 0 0" rpy="0 0 0"/>
    <limit effort="1000.0" lower="-1" upper="1" velocity="0.5"/>
  </joint>

  <joint name="rail_link" type="fixed">
    <parent link="rail"/>
    <child link="z_column"/>
    <axis xyz="0 1 0"/>
    <origin xyz="0.03005 -0.0198 0.05" rpy="0 0 0"/>
    <limit effort="1000.0" lower="0" upper="0" velocity="0.5"/>
  </joint>

</robot>
