<?xml version="1.0"?>
<robot name="Thermocycler" xmlns:xacro="http://www.ros.org/wiki/xacro">


  <!-- Links -->
  <xacro:macro name="Thermocycler" params = "prefix">
  <link name="${prefix}Thermocycler_Base">
    <visual>
      <origin xyz="0 0.5 1.042" rpy="1.5708 0 0"/>
      <geometry>
        <mesh filename="package://pf400_description/meshes/thermocycler_base.STL" scale="0.001 0.001 0.001"/>
      </geometry>
      <material name="light_grey"/>
    </visual>
  </link>

  <link name="${prefix}Thermocycler_Cap">
    <visual>
      <origin xyz="0 0 0" rpy="0 0 0"/>
      <geometry>
        <mesh filename="package://pf400_description/meshes/thermocycler_cap.STL" scale="0.001 0.001 0.001"/>
      </geometry>
      <material name="red"/>
    </visual>
  </link>

  <!-- Joints -->

  <joint name="Thermocycler_Cap" type="revolute">
    <parent link="${prefix}Thermocycler_Base"/>
    <child link="${prefix}Thermocycler_Cap"/>
    <axis xyz="-1 0 0"/>
    <origin xyz="0 0.466 1.05" rpy="1.5708 0 0"/>
    <limit effort="1000.0" lower="0" upper="1.2" velocity="0.5"/>
  </joint>
  </xacro:macro>

</robot>
